Traceback (most recent call last):
  File "/workspaces/mpesa-integration/frappe-bench/env/lib/python3.10/site-packages/redis/connection.py", line 699, in connect
    sock = self.retry.call_with_retry(
  File "/workspaces/mpesa-integration/frappe-bench/env/lib/python3.10/site-packages/redis/retry.py", line 46, in call_with_retry
    return do()
  File "/workspaces/mpesa-integration/frappe-bench/env/lib/python3.10/site-packages/redis/connection.py", line 700, in <lambda>
    lambda: self._connect(), lambda error: self.disconnect(error)
  File "/workspaces/mpesa-integration/frappe-bench/env/lib/python3.10/site-packages/redis/connection.py", line 1002, in _connect
    raise err
  File "/workspaces/mpesa-integration/frappe-bench/env/lib/python3.10/site-packages/redis/connection.py", line 990, in _connect
    sock.connect(socket_address)
ConnectionRefusedError: [Errno 111] Connection refused

During handling of the above exception, another exception occurred:

Traceback (most recent call last):
  File "/home/codespace/.python/current/lib/python3.10/runpy.py", line 196, in _run_module_as_main
    return _run_code(code, main_globals, None,
  File "/home/codespace/.python/current/lib/python3.10/runpy.py", line 86, in _run_code
    exec(code, run_globals)
  File "/workspaces/mpesa-integration/frappe-bench/apps/frappe/frappe/utils/bench_helper.py", line 104, in <module>
    main()
  File "/workspaces/mpesa-integration/frappe-bench/apps/frappe/frappe/utils/bench_helper.py", line 19, in main
    click.Group(commands=commands)(prog_name="bench")
  File "/workspaces/mpesa-integration/frappe-bench/env/lib/python3.10/site-packages/click/core.py", line 1130, in __call__
    return self.main(*args, **kwargs)
  File "/workspaces/mpesa-integration/frappe-bench/env/lib/python3.10/site-packages/click/core.py", line 1055, in main
    rv = self.invoke(ctx)
  File "/workspaces/mpesa-integration/frappe-bench/env/lib/python3.10/site-packages/click/core.py", line 1657, in invoke
    return _process_result(sub_ctx.command.invoke(sub_ctx))
  File "/workspaces/mpesa-integration/frappe-bench/env/lib/python3.10/site-packages/click/core.py", line 1657, in invoke
    return _process_result(sub_ctx.command.invoke(sub_ctx))
  File "/workspaces/mpesa-integration/frappe-bench/env/lib/python3.10/site-packages/click/core.py", line 1404, in invoke
    return ctx.invoke(self.callback, **ctx.params)
  File "/workspaces/mpesa-integration/frappe-bench/env/lib/python3.10/site-packages/click/core.py", line 760, in invoke
    return __callback(*args, **kwargs)
  File "/workspaces/mpesa-integration/frappe-bench/apps/frappe/frappe/commands/scheduler.py", line 208, in start_worker
    start_worker(
  File "/workspaces/mpesa-integration/frappe-bench/apps/frappe/frappe/utils/background_jobs.py", line 265, in start_worker
    worker.work(
  File "/workspaces/mpesa-integration/frappe-bench/env/lib/python3.10/site-packages/rq/worker.py", line 645, in work
    self.unsubscribe()
  File "/workspaces/mpesa-integration/frappe-bench/env/lib/python3.10/site-packages/rq/worker.py", line 550, in unsubscribe
    self.pubsub.unsubscribe()
  File "/workspaces/mpesa-integration/frappe-bench/env/lib/python3.10/site-packages/redis/client.py", line 1659, in unsubscribe
    return self.execute_command("UNSUBSCRIBE", *args)
  File "/workspaces/mpesa-integration/frappe-bench/env/lib/python3.10/site-packages/redis/client.py", line 1469, in execute_command
    self.connection = self.connection_pool.get_connection(
  File "/workspaces/mpesa-integration/frappe-bench/env/lib/python3.10/site-packages/redis/connection.py", line 1457, in get_connection
    connection.connect()
  File "/workspaces/mpesa-integration/frappe-bench/env/lib/python3.10/site-packages/redis/connection.py", line 705, in connect
    raise ConnectionError(self._error_message(e))
redis.exceptions.ConnectionError: Error 111 connecting to localhost:11000. Connection refused.
